{"uuid": "6443c98c-b514-40c9-87d2-45cc8a162b41", "children": ["82dcfa65-8b28-4fba-9f83-0df2c73561c7"], "befores": [{"name": "create_driver", "status": "broken", "statusDetails": {"message": "ValueError: response body:\n<?xml version='1.0' encoding='UTF-8'?><Error><Code>AccessDenied</Code><Message>Access denied.</Message><Details>We're sorry, but this service is not available in your location</Details></Error>\nrequest url:\nhttps://storage.googleapis.com/chrome-for-testing-public/132.0.6834.110/mac-arm64/chromedriver-mac-arm64.zip\nresponse headers:\n{'X-GUploader-UploadID': 'AFIdbgSHfqCe1FN5PgyKXapmaZnXEfJKZ1mhL5b-1HbeQYI6-hZKI_ZTrMsE04_OQLZ_hjlCyKA7NI0', 'Content-Type': 'application/xml; charset=UTF-8', 'Content-Length': '193', 'Date': 'Fri, 24 Jan 2025 08:24:29 GMT', 'Expires': 'Fri, 24 Jan 2025 08:24:29 GMT', 'Cache-Control': 'private, max-age=0', 'Server': 'UploadServer', 'Alt-Svc': 'h3=\":443\"; ma=2592000,h3-29=\":443\"; ma=2592000'}\n\n", "trace": "  File \"/Users/mohsenakbari/Downloads/Python-Selenium-Pytest-main/.venv/lib/python3.10/site-packages/pluggy/callers.py\", line 187, in _multicall\n    res = hook_impl.function(*args)\n  File \"/Users/mohsenakbari/Downloads/Python-Selenium-Pytest-main/.venv/lib/python3.10/site-packages/_pytest/fixtures.py\", line 1123, in pytest_fixture_setup\n    result = call_fixture_func(fixturefunc, request, kwargs)\n  File \"/Users/mohsenakbari/Downloads/Python-Selenium-Pytest-main/.venv/lib/python3.10/site-packages/_pytest/fixtures.py\", line 895, in call_fixture_func\n    fixture_result = next(generator)\n  File \"/Users/mohsenakbari/Downloads/Python-Selenium-Pytest-main/tests/conftest.py\", line 61, in create_driver\n    driver = webdriver.Chrome(service=Service(ChromeDriverManager().install()), options=opts)\n  File \"/Users/mohsenakbari/Downloads/Python-Selenium-Pytest-main/.venv/lib/python3.10/site-packages/webdriver_manager/chrome.py\", line 40, in install\n    driver_path = self._get_driver_binary_path(self.driver)\n  File \"/Users/mohsenakbari/Downloads/Python-Selenium-Pytest-main/.venv/lib/python3.10/site-packages/webdriver_manager/core/manager.py\", line 40, in _get_driver_binary_path\n    file = self._download_manager.download_file(driver.get_driver_download_url(os_type))\n  File \"/Users/mohsenakbari/Downloads/Python-Selenium-Pytest-main/.venv/lib/python3.10/site-packages/webdriver_manager/core/download_manager.py\", line 29, in download_file\n    response = self._http_client.get(url)\n  File \"/Users/mohsenakbari/Downloads/Python-Selenium-Pytest-main/.venv/lib/python3.10/site-packages/webdriver_manager/core/http.py\", line 36, in get\n    self.validate_response(resp)\n  File \"/Users/mohsenakbari/Downloads/Python-Selenium-Pytest-main/.venv/lib/python3.10/site-packages/webdriver_manager/core/http.py\", line 19, in validate_response\n    raise ValueError(\n"}, "start": 1737707066317, "stop": 1737707069911}], "start": 1737707066317, "stop": 1737707069962}